Workbook

Sheet NHAP LIEU
A2: CONG TY TNHH TNE&C - HE THONG BAO CAO NGAY | J2: NHAP LIEU HANG NGAY
A3: Kinh gui: BAN GIAM DOC | Nguoi lap: Lê Quỳnh Ngân___________ | Bo phan xac nhan: _________________________
A5: NGAY BAO CAO: | D5: 46112 | F5: <-- Thay o D5 moi sang | Vang=Nhap tay | Xanh=Tu tinh cong thuc
A7: I. TINH HINH TIEN DO THI CONG CAC DU AN
A8: STT | B8: TEN DU AN | C8: KH (%) | D8: LK HOM QUA (%) | E8: HOM NAY (%) | F8: LK HOM NAY (D+E, tu tinh) | G8: GT HD (ty dong) | H8: GT SAN LUONG (ty dong) | I8: GT NGHIEM THU (ty dong) | J8: % SL/HD | K8: CANH BAO | L8: CONG VIEC TRONG NGAY | M8: VUONG MAC / DANH GIA
A9: 1 | B9: XLNT TAY NINH | C9: 100 | D9: 0.2842 | E9: 0.0019 | F9: =D9+E9 -> 0.2861 | G9: 63.199 | H9: 29.551 | I9: 18.008 | J9: =IF(OR(G9=0,G9=""),"",H9/G9) -> 0.46758651 | K9: =IF(OR(G9=0,G9=""),"—",IF(J9<F9,"⚠ SL < TD "&TEXT((F9-J9)*100,"0.0")&"%",IF(J9<0.1,"⚠ SL < 10%","✓"))) -> ✓ | L9: * KL Công ty Đại Nam - Đổ bê tông hố ga hộp đấu nối hộ dân và hộp chuyển hướng (05 cấu kiện), KL Đại Nam 5/170/920 - Thảm BTN đường Hoàng Lê Kha lớp 2, bảo dưỡng BTN. * KL Công ty Toàn Thắng - Đổ bê tông thân hố ga TO chính (02 cấu kiện), KL Toàn Thắng 2/206/222 - Đổ bê tông cổ hố ga TO chính (02 cấu kiện), KL Toàn Thắng 2/166/222, lắp đặt nắp gang 2/147/222 - Vận chuyển, lắp dựng hố ga TO chính trên tuyến, KL Toàn Thắng 3/171/222 - Đổ bê tông hố ga hộp đấu nối hộ dân và hộp chuyển hướng (05 cấu kiện), KL Toàn Thắng 5/265/2224 - Lắp đặt ống HDPE trên tuyến, KL Toàn Thắng OD355 120/3448/5252, OD450 0/289/367 (M) - Thi công tuyến ống cấp 3, lắp đặt ống uPVC 160 KL 80/830/14647 (M)
A10: 2 | B10: RACH XUYEN TAM | C10: 100 | D10: 0.10315789 | E10: =1/950 -> 0.0010526316 | F10: =D10+E10 -> 0.10421053 | J10: =IF(OR(G10=0,G10=""),"",H10/G10) | K10: =IF(OR(G10=0,G10=""),"—",IF(J10<F10,"⚠ SL < TD "&TEXT((F10-J10)*100,"0.0")&"%",IF(J10<0.1,"⚠ SL < 10%","✓"))) -> — | M10: 1. Vướng mặt bằng 2. P.KHDA chưa trình BGĐ giá thi công văn phòng BĐH
A11: 3 | B11: HUONG LO 11 | C11: 100 | D11: 0.4004 | E11: 0.0028 | F11: =D11+E11 -> 0.4032 | G11: 157.345 | H11: 12.689 | I11: 5.294 | J11: =IF(OR(G11=0,G11=""),"",H11/G11) -> 0.080644444 | K11: =IF(OR(G11=0,G11=""),"—",IF(J11<F11,"⚠ SL < TD "&TEXT((F11-J11)*100,"0.0")&"%",IF(J11<0.1,"⚠ SL < 10%","✓"))) -> ⚠ SL < TD 32% | L11: - Tiến độ thực hiện dự án hơn 40% Tiến độ tổng thể. => Đề xuất BGĐ đôn đôc phía Cty Phước Vạn Thịnh. | M11: Vướng mặt bằng
A12: 4 | B12: KCN CA NA | C12: 100 | D12: 0 | E12: 0 | F12: =D12+E12 -> 0 | J12: =IF(OR(G12=0,G12=""),"",H12/G12) | K12: =IF(OR(G12=0,G12=""),"—",IF(J12<F12,"⚠ SL < TD "&TEXT((F12-J12)*100,"0.0")&"%",IF(J12<0.1,"⚠ SL < 10%","✓"))) -> — | L12: - Công tác pháp lý chuẩn bị đầu vào dự án. | M12: Chưa bàn giao MB
A13: 5 | B13: DMT TRA VINH 2 | C13: 100 | D13: 0.3486 | E13: 0.0027 | F13: =D13+E13 -> 0.3513 | G13: 568.791 | H13: 13.811 | J13: =IF(OR(G13=0,G13=""),"",H13/G13) -> 0.024281327 | K13: =IF(OR(G13=0,G13=""),"—",IF(J13<F13,"⚠ SL < TD "&TEXT((F13-J13)*100,"0.0")&"%",IF(J13<0.1,"⚠ SL < 10%","✓"))) -> ⚠ SL < TD 33% | L13: - Gia công cốt thép; - Đỗ bê tông cọc 220x220x3900mm sản lượng 152/9.661/12.792 + Sản lượng nhà thầu Yên Phúc đã đúc 50/1.109 cọc + Sản lượng nhà thầu Xuân Sơn Hải Dương đã đúc: 42/40 cọc - Bơm cát san lắp mặt bằng sản lượng: 250m3/2850m3 - Vận chuyển cọc từ bãi gia công vào nhà máy ( Nhà Thầu Yên Phúc ) + Sản lượng vận chuyển 120/380 cọc - San mặt bằng nền bãi chứa pin | M13: 1. Chưa có pháp lý 2. P.KHDA chưa trình BGĐ giá thầu phụ chào bãi chứa pin.
A14: 6 | B14: TINH LO 8 | C14: 100 | D14: 0.0022222222 | E14: 2.2222222e-05 | F14: =D14+E14 -> 0.0022444444 | G14: 127.72 | J14: =IF(OR(G14=0,G14=""),"",H14/G14) -> 0 | K14: =IF(OR(G14=0,G14=""),"—",IF(J14<F14,"⚠ SL < TD "&TEXT((F14-J14)*100,"0.0")&"%",IF(J14<0.1,"⚠ SL < 10%","✓"))) -> ⚠ SL < TD 00% | L14: - Dự kiến 01/04/2026 Họp CĐT,TVGS, Nhà thầu về tiến độ và khó khăn thi công dự án. | M14: —
A15: 7 | B15: CAU MA DA | C15: 100 | D15: 0 | E15: 0 | F15: =D15+E15 -> 0 | G15: 91.839 | J15: =IF(OR(G15=0,G15=""),"",H15/G15) -> 0 | K15: =IF(OR(G15=0,G15=""),"—",IF(J15<F15,"⚠ SL < TD "&TEXT((F15-J15)*100,"0.0")&"%",IF(J15<0.1,"⚠ SL < 10%","✓"))) -> ⚠ SL < 10% | L15: - Dự kiến đầu tháng 4 sẽ khoan cọc nhồi. - Kế hoạch ký PLHĐ điều chỉnh 23/04/2026 | M15: Đang chờ CĐT làm việc TK để ra bản vẽ cọc
A16: 8 | B16: KDC THUONG PHUOC | C16: 100 | D16: 0.24466452 | E16: =1/372 -> 0.002688172 | F16: =D16+E16 -> 0.24735269 | G16: 95.092 | H16: 1.2 | J16: =IF(OR(G16=0,G16=""),"",H16/G16) -> 0.012619358 | K16: =IF(OR(G16=0,G16=""),"—",IF(J16<F16,"⚠ SL < TD "&TEXT((F16-J16)*100,"0.0")&"%",IF(J16<0.1,"⚠ SL < 10%","✓"))) -> ⚠ SL < TD 23% | L16: - Gia công thép hố ga; - Gia công lắp dựng ván khuôn hố ga; - Sửa máy taluy đê vây; - Đổ bê tông hố ga. | M16: —
A17: 9 | B17: CONG VAM LEO | C17: 100 | D17: 0 | E17: 0 | F17: =D17+E17 -> 0 | J17: =IF(OR(G17=0,G17=""),"",H17/G17) | K17: =IF(OR(G17=0,G17=""),"—",IF(J17<F17,"⚠ SL < TD "&TEXT((F17-J17)*100,"0.0")&"%",IF(J17<0.1,"⚠ SL < 10%","✓"))) -> — | L17: - Rà bóc khối lượng thép | M17: Dự kiến 20/4 khởi công
A18: TONG / BINH QUAN | F18: =AVERAGE(F9:F17) -> 0.15493418 | G18: =SUM(G9:G17) -> 1103.986 | H18: =SUM(H9:H17) -> 57.251 | I18: =SUM(I9:I17) -> 23.302 | J18: =IF(OR(G18=0,G18=""),"",H18/G18) -> 0.051858447
A20: II. CHI TIEN TRONG NGAY
A21: STT | B21: DU AN | C21: DON VI NHAN | E21: NOI DUNG CHI | J21: SO TIEN (dong)
A22: 1 | B22: Chung | C22: Ms Như | E22: Thanh toán chi phí lưu trú công tác Mr Phát GĐ CN Miền Trung | J22: 1500000
A23: 2 | B23: Chung | C23: BHXH | E23: Thanh toán chi phí bảo hiểm tháng 2/2026 | J23: 208310964
A24: 5 | B24: XLNT Tây Ninh | C24: Cty Đại Nam | E24: Tạm ứng HĐ giao khoán thi công | J24: 919606364
A25: 6 | B25: XLNT Tây Ninh | C25: Cty Enviro world | E25: Tạm ứng HĐ mua bán vật tư | J25: 971704830
A26: 7 | B26: Chống hạn | C26: Mr Duy Hưng | E26: Thanh toán chi phí công tác | J26: 6249733
A27: 8 | B27: Chung | C27: Ms Quỳnh | E27: Tạm ứng chi phí văn phòng 4/2026 | J27: 5000000
A28: 9 | B28: Chung | C28: Cty SAIGONCARS | E28: Thanh toán chi phí thuê xe và cọc xe | J28: 29120000
A29: 10
A30: 11
A31: TONG CHI TRONG NGAY | J31: =SUM(J22:J30) -> 2141491891
A33: III. THU TIEN TRONG NGAY
A34: STT | B34: DU AN | C34: NGUON THU | E34: NOI DUNG THU | J34: SO TIEN (dong)
A35: 1
A36: 2
A37: 3
A38: 4
A39: 5
A40: TONG THU TRONG NGAY | J40: =SUM(J35:J39) -> 0
A42: IV. GHI CHU / HO SO DA KY / KIEN NGHI GIAM DOC
A43: 1. Tờ trình Điều chỉnh giá phần thi công, điều chỉnh giá phần bơm cát dự án ĐMT Trà Vinh 2
A44: 2. Thanh toán chi phí Mr Duy Hưng đi công tác Hà Nội dự án Chống hạn
A45: 3. Ký hoàn hồ sơ thanh toán chi phí tiếp khách dự án Rạch Xuyên Tâm
A46: 4. Yêu cầu cấp Laptop Ms Phú phòng KHDA
...

Sheet BAO CAO IN
A2: TRUNGNAM E&C | J2: ='NHAP LIEU'!D5 -> 46112
A4: BÁO CÁO NGÀY - Kính gửi: Giám đốc
B5: =9-C5 -> 3 | C5: 6 | F5: =H21 -> 57.251 | H5: =I21 -> 23.302
B6: Chưa khởi công | C6: Khởi công | F6: Giá trị SL | H6: Giá trị nghiệm thu
A8: I. TINH HINH TIEN DO THI CONG
A9: STT | B9: TÊN DỰ ÁN | C9: KH (%) | D9: LK Tiến độ hôm qua (%) | E9: Tiến độ hôm nay (%) | F9: LK Tiến độ đến hôm nay (%) | G9: GT HĐ (ty) | H9: GT SẢN LƯỢNG | I9: GT NGHIỆM THU | J9: % SL/HĐ | K9: CẢNH BÁO | L9: CÔNG VIỆC TRONG NGÀY | M9: VƯỚNG MẮC
A10: A | B10: ĐÃ KHỞI CÔNG
A11: ='NHAP LIEU'!A9 -> 1 | B11: ='NHAP LIEU'!B9 -> XLNT TAY NINH | C11: ='NHAP LIEU'!C9 -> 100 | D11: ='NHAP LIEU'!D9 -> 0.2842 | E11: ='NHAP LIEU'!E9 -> 0.0019 | F11: ='NHAP LIEU'!F9 -> 0.2861 | G11: ='NHAP LIEU'!G9 -> 63.199 | H11: ='NHAP LIEU'!H9 -> 29.551 | ... M11: ='NHAP LIEU'!M9 -> 0
A12: ='NHAP LIEU'!A10 -> 2 | B12: ='NHAP LIEU'!B10 -> RACH XUYEN TAM | C12: ='NHAP LIEU'!C10 -> 100 | D12: ='NHAP LIEU'!D10 -> 0.10315789 | E12: ='NHAP LIEU'!E10 -> 0.0010526316 | F12: ='NHAP LIEU'!F10 -> 0.10421053 | G12: ='NHAP LIEU'!G10 -> 0 | H12: ='NHAP LIEU'!H10 -> 0 | ... M12: ='NHAP LIEU'!M10 -> 1. Vướng mặt bằng 2. P.KHDA chưa trình BGĐ giá thi công văn phòng BĐH
A13: ='NHAP LIEU'!A11 -> 3 | B13: ='NHAP LIEU'!B11 -> HUONG LO 11 | C13: ='NHAP LIEU'!C11 -> 100 | D13: ='NHAP LIEU'!D11 -> 0.4004 | E13: ='NHAP LIEU'!E11 -> 0.0028 | F13: ='NHAP LIEU'!F11 -> 0.4032 | G13: ='NHAP LIEU'!G11 -> 157.345 | H13: ='NHAP LIEU'!H11 -> 12.689 | ... M13: ='NHAP LIEU'!M11 -> Vướng mặt bằng
A14: 4 | B14: ='NHAP LIEU'!B13 -> DMT TRA VINH 2 | C14: ='NHAP LIEU'!C13 -> 100 | D14: ='NHAP LIEU'!D13 -> 0.3486 | E14: ='NHAP LIEU'!E13 -> 0.0027 | F14: ='NHAP LIEU'!F13 -> 0.3513 | G14: ='NHAP LIEU'!G13 -> 568.791 | H14: ='NHAP LIEU'!H13 -> 13.811 | I14: ='NHAP LIEU'!I13 -> 0 | ... M14: ='NHAP LIEU'!M13 -> 1. Chưa có pháp lý 2. P.KHDA chưa trình BGĐ giá thầu phụ chào bãi chứa pin.
A15: 5 | B15: ='NHAP LIEU'!B14 -> TINH LO 8 | C15: ='NHAP LIEU'!C14 -> 100 | D15: ='NHAP LIEU'!D14 -> 0.0022222222 | E15: ='NHAP LIEU'!E14 -> 2.2222222e-05 | F15: ='NHAP LIEU'!F14 -> 0.0022444444 | G15: ='NHAP LIEU'!G14 -> 127.72 | H15: ='NHAP LIEU'!H14 -> 0 | I15: ='NHAP LIEU'!I14 -> 0 | ... M15: ='NHAP LIEU'!M14 -> —
A16: 6 | B16: ='NHAP LIEU'!B16 -> KDC THUONG PHUOC | C16: ='NHAP LIEU'!C16 -> 100 | D16: ='NHAP LIEU'!D16 -> 0.24466452 | E16: ='NHAP LIEU'!E16 -> 0.002688172 | F16: ='NHAP LIEU'!F16 -> 0.24735269 | G16: ='NHAP LIEU'!G16 -> 95.092 | H16: ='NHAP LIEU'!H16 -> 1.2 | I16: ='NHAP LIEU'!I16 -> 0 | ... M16: ='NHAP LIEU'!M16 -> —
A17: B | B17: CHƯA KHỞI CÔNG
A18: 7 | B18: ='NHAP LIEU'!B12 -> KCN CA NA | C18: ='NHAP LIEU'!C12 -> 100 | D18: ='NHAP LIEU'!D12 -> 0 | E18: ='NHAP LIEU'!E12 -> 0 | F18: ='NHAP LIEU'!F12 -> 0 | G18: ='NHAP LIEU'!G12 -> 0 | H18: ='NHAP LIEU'!H12 -> 0 | I18: ='NHAP LIEU'!I12 -> 0 | ... M18: ='NHAP LIEU'!M12 -> Chưa bàn giao MB
A19: 8 | B19: ='NHAP LIEU'!B15 -> CAU MA DA | C19: ='NHAP LIEU'!C15 -> 100 | D19: ='NHAP LIEU'!D15 -> 0 | E19: ='NHAP LIEU'!E15 -> 0 | F19: ='NHAP LIEU'!F15 -> 0 | G19: ='NHAP LIEU'!G15 -> 91.839 | H19: ='NHAP LIEU'!H15 -> 0 | I19: ='NHAP LIEU'!I15 -> 0 | ... M19: ='NHAP LIEU'!M15 -> Đang chờ CĐT làm việc TK để ra bản vẽ cọc
A20: 9 | B20: ='NHAP LIEU'!B17 -> CONG VAM LEO | C20: ='NHAP LIEU'!C17 -> 100 | D20: ='NHAP LIEU'!D17 -> 0 | E20: ='NHAP LIEU'!E17 -> 0 | F20: ='NHAP LIEU'!F17 -> 0 | G20: ='NHAP LIEU'!G17 -> 0 | H20: ='NHAP LIEU'!H17 -> 0 | I20: ='NHAP LIEU'!I17 -> 0 | ... M20: ='NHAP LIEU'!M17 -> Dự kiến 20/4 khởi công
A21: TONG / BINH QUAN | F21: =AVERAGE(F11:F20) -> 0.15493418 | G21: =SUM(G11:G20) -> 1103.986 | H21: =SUM(H11:H20) -> 57.251 | I21: =SUM(I11:I20) -> 23.302 | J21: =IF(OR(G21=0,G21=""),"",H21/G21) -> 0.051858447
A23: II. CHI TIEN TRONG NGAY | J23: ='NHAP LIEU'!J31 -> 2141491891
A24: 1 | B24: ='NHAP LIEU'!B22 -> Chung | C24: ='NHAP LIEU'!C22 -> Ms Như | E24: ='NHAP LIEU'!E22 -> Thanh toán chi phí lưu trú công tác Mr Phát GĐ CN Miền Trung | J24: ='NHAP LIEU'!J22 -> 1500000
A25: 2 | B25: ='NHAP LIEU'!B23 -> Chung | C25: ='NHAP LIEU'!C23 -> BHXH | E25: ='NHAP LIEU'!E23 -> Thanh toán chi phí bảo hiểm tháng 2/2026 | J25: ='NHAP LIEU'!J23 -> 208310964
A26: 3 | B26: ='NHAP LIEU'!B24 -> XLNT Tây Ninh | C26: ='NHAP LIEU'!C24 -> Cty Đại Nam | E26: ='NHAP LIEU'!E24 -> Tạm ứng HĐ giao khoán thi công | J26: ='NHAP LIEU'!J24 -> 919606364
A27: 4 | B27: ='NHAP LIEU'!B25 -> XLNT Tây Ninh | C27: ='NHAP LIEU'!C25 -> Cty Enviro world | E27: ='NHAP LIEU'!E25 -> Tạm ứng HĐ mua bán vật tư | J27: ='NHAP LIEU'!J25 -> 971704830
A28: 5 | B28: ='NHAP LIEU'!B26 -> Chống hạn | C28: ='NHAP LIEU'!C26 -> Mr Duy Hưng | E28: ='NHAP LIEU'!E26 -> Thanh toán chi phí công tác | J28: ='NHAP LIEU'!J26 -> 6249733
A29: 6 | B29: ='NHAP LIEU'!B27 -> Chung | C29: ='NHAP LIEU'!C27 -> Ms Quỳnh | E29: ='NHAP LIEU'!E27 -> Tạm ứng chi phí văn phòng 4/2026 | J29: ='NHAP LIEU'!J27 -> 5000000
A30: 7 | B30: ='NHAP LIEU'!B28 -> Chung | C30: ='NHAP LIEU'!C28 -> Cty SAIGONCARS | E30: ='NHAP LIEU'!E28 -> Thanh toán chi phí thuê xe và cọc xe | J30: ='NHAP LIEU'!J28 -> 29120000
A31: 8 | B31: ='NHAP LIEU'!B29 -> 0 | C31: ='NHAP LIEU'!C29 -> 0 | E31: ='NHAP LIEU'!E29 -> 0 | J31: ='NHAP LIEU'!J29 -> 0
A32: 9 | B32: ='NHAP LIEU'!B30 -> 0 | C32: ='NHAP LIEU'!C30 -> 0 | E32: ='NHAP LIEU'!E30 -> 0 | J32: ='NHAP LIEU'!J30 -> 0
A34: III. THU TIEN TRONG NGAY | J34: ='NHAP LIEU'!J40 -> 0
A35: 1 | B35: ='NHAP LIEU'!B35 -> 0 | C35: ='NHAP LIEU'!C35 -> 0 | E35: ='NHAP LIEU'!E35 -> 0 | J35: ='NHAP LIEU'!J35 -> 0
A36: 2 | B36: ='NHAP LIEU'!B36 -> 0 | C36: ='NHAP LIEU'!C36 -> 0 | E36: ='NHAP LIEU'!E36 -> 0 | J36: ='NHAP LIEU'!J36 -> 0
A37: 3 | B37: ='NHAP LIEU'!B37 -> 0 | C37: ='NHAP LIEU'!C37 -> 0 | E37: ='NHAP LIEU'!E37 -> 0 | J37: ='NHAP LIEU'!J37 -> 0
A38: 4 | B38: ='NHAP LIEU'!B38 -> 0 | C38: ='NHAP LIEU'!C38 -> 0 | E38: ='NHAP LIEU'!E38 -> 0 | J38: ='NHAP LIEU'!J38 -> 0
A39: 5 | B39: ='NHAP LIEU'!B39 -> 0 | C39: ='NHAP LIEU'!C39 -> 0 | E39: ='NHAP LIEU'!E39 -> 0 | J39: ='NHAP LIEU'!J39 -> 0
A41: IV. GHI CHU / HO SO DA KY / KIEN NGHI GIAM DOC
A42: ='NHAP LIEU'!A43 -> 1. Tờ trình Điều chỉnh giá phần thi công, điều chỉnh giá phần bơm cát dự án ĐMT Trà Vinh 2
A43: ='NHAP LIEU'!A44 -> 2. Thanh toán chi phí Mr Duy Hưng đi công tác Hà Nội dự án Chống hạn
A44: ='NHAP LIEU'!A45 -> 3. Ký hoàn hồ sơ thanh toán chi phí tiếp khách dự án Rạch Xuyên Tâm
A45: ='NHAP LIEU'!A46 -> 4. Yêu cầu cấp Laptop Ms Phú phòng KHDA
A46: ='NHAP LIEU'!A47 -> 5. Giấy UQ Mr Thái, Mr Dũng đi họp dự án Tỉnh Lộ 8
...

Sheet HUONG DAN
A2: HUONG DAN SU DUNG - BAO CAO NGAY TNE&C
A4: >>> QUY UOC MAU SAC
B5: Vang (FFFF99) | C5: O nhap tay - bat buoc dien moi ngay
B6: Xanh nhat (DBEAFE) | C6: O cong thuc tu tinh - KHONG sua
B7: Xanh chu (0000FF) | C7: So hardcode san co the thay doi
A8: >>> QUY TRINH HANG NGAY
B9: Buoc 1 | C9: Mo sheet NHAP LIEU
B10: Buoc 2 | C10: Sua o D5 = ngay hom nay (DD/MM/YYYY)
B11: Buoc 3 | C11: Dien % Hom nay cot E tung du an (cot F tu tinh)
B12: Buoc 4 | C12: Nhap Cong viec trong ngay (cot I)
B13: Buoc 5 | C13: Chon Vuong mac tu dropdown (cot J)
B14: Buoc 6 | C14: Cap nhat Gia tri TH / NT neu co nghiem thu moi
B15: Buoc 7 | C15: Kiem tra / chinh sua bang CHI TIEN
B16: Buoc 8 | C16: Dien bang THU TIEN neu co phat sinh
B17: Buoc 9 | C17: Ghi chu / kien nghi Giam doc (Section IV)
B18: Buoc 10 | C18: Chuyen sang sheet BAO CAO IN -> xem truoc -> in/xuat PDF
A19: >>> XUAT PDF
B20: Excel | C20: File -> Export -> Create PDF/XPS
B21: LibreOffice | C21: File -> Export as PDF -> OK
B22: Ten file goi y | C22: TNEC_YYYY_MM_DD_Bao_cao_ngay.xlsx
A23: >>> LUU Y QUAN TRONG
B24: KHONG XOA HANG/COT | C24: Se pha vo cong thuc tham chieu giua 2 sheet
B25: Them khoan chi | C25: Insert row giua cac hang trong vung CHI TIEN
B26: Them du an | C26: Sao chep hang du an -> dan xuong -> cap nhat thong tin
